[2025-01-30T08:21:04.366+0000] {local_task_job_runner.py:123} INFO - ::group::Pre task execution logs
[2025-01-30T08:21:04.375+0000] {taskinstance.py:2613} INFO - Dependencies all met for dep_context=non-requeueable deps ti=<TaskInstance: etl_orders.load_to_staging scheduled__2025-01-29T00:00:00+00:00 [queued]>
[2025-01-30T08:21:04.379+0000] {taskinstance.py:2613} INFO - Dependencies all met for dep_context=requeueable deps ti=<TaskInstance: etl_orders.load_to_staging scheduled__2025-01-29T00:00:00+00:00 [queued]>
[2025-01-30T08:21:04.379+0000] {taskinstance.py:2866} INFO - Starting attempt 1 of 2
[2025-01-30T08:21:04.390+0000] {taskinstance.py:2889} INFO - Executing <Task(PythonOperator): load_to_staging> on 2025-01-29 00:00:00+00:00
[2025-01-30T08:21:04.410+0000] {standard_task_runner.py:72} INFO - Started process 2795 to run task
[2025-01-30T08:21:04.420+0000] {standard_task_runner.py:104} INFO - Running: ['airflow', 'tasks', 'run', 'etl_orders', 'load_to_staging', 'scheduled__2025-01-29T00:00:00+00:00', '--job-id', '32', '--raw', '--subdir', 'DAGS_FOLDER/etl_movies_sp.py', '--cfg-path', '/tmp/tmpuotb2n4_']
[2025-01-30T08:21:04.425+0000] {standard_task_runner.py:105} INFO - Job 32: Subtask load_to_staging
[2025-01-30T08:21:04.530+0000] {task_command.py:467} INFO - Running <TaskInstance: etl_orders.load_to_staging scheduled__2025-01-29T00:00:00+00:00 [running]> on host 76fb3969a3aa
[2025-01-30T08:21:04.648+0000] {taskinstance.py:3132} INFO - Exporting env vars: AIRFLOW_CTX_DAG_OWNER='airflow' AIRFLOW_CTX_DAG_ID='etl_orders' AIRFLOW_CTX_TASK_ID='load_to_staging' AIRFLOW_CTX_EXECUTION_DATE='2025-01-29T00:00:00+00:00' AIRFLOW_CTX_TRY_NUMBER='1' AIRFLOW_CTX_DAG_RUN_ID='scheduled__2025-01-29T00:00:00+00:00'
[2025-01-30T08:21:04.649+0000] {taskinstance.py:731} INFO - ::endgroup::
[2025-01-30T08:21:04.662+0000] {etl_movies_sp.py:26} INFO - Memulai proses loading data ke staging...
[2025-01-30T08:21:54.714+0000] {taskinstance.py:3311} ERROR - Task failed with exception
Traceback (most recent call last):
  File "/home/airflow/.local/lib/python3.12/site-packages/mysql/connector/connection_cext.py", line 706, in cmd_query
    self._cmysql.query(
_mysql_connector.MySQLInterfaceError: Got a packet bigger than 'max_allowed_packet' bytes

The above exception was the direct cause of the following exception:

Traceback (most recent call last):
  File "/home/airflow/.local/lib/python3.12/site-packages/airflow/models/taskinstance.py", line 767, in _execute_task
    result = _execute_callable(context=context, **execute_callable_kwargs)
             ^^^^^^^^^^^^^^^^^^^^^^^^^^^^^^^^^^^^^^^^^^^^^^^^^^^^^^^^^^^^^
  File "/home/airflow/.local/lib/python3.12/site-packages/airflow/models/taskinstance.py", line 733, in _execute_callable
    return ExecutionCallableRunner(
           ^^^^^^^^^^^^^^^^^^^^^^^^
  File "/home/airflow/.local/lib/python3.12/site-packages/airflow/utils/operator_helpers.py", line 252, in run
    return self.func(*args, **kwargs)
           ^^^^^^^^^^^^^^^^^^^^^^^^^^
  File "/home/airflow/.local/lib/python3.12/site-packages/airflow/models/baseoperator.py", line 422, in wrapper
    return func(self, *args, **kwargs)
           ^^^^^^^^^^^^^^^^^^^^^^^^^^^
  File "/home/airflow/.local/lib/python3.12/site-packages/airflow/operators/python.py", line 238, in execute
    return_value = self.execute_callable()
                   ^^^^^^^^^^^^^^^^^^^^^^^
  File "/home/airflow/.local/lib/python3.12/site-packages/airflow/operators/python.py", line 256, in execute_callable
    return runner.run(*self.op_args, **self.op_kwargs)
           ^^^^^^^^^^^^^^^^^^^^^^^^^^^^^^^^^^^^^^^^^^^
  File "/home/airflow/.local/lib/python3.12/site-packages/airflow/utils/operator_helpers.py", line 252, in run
    return self.func(*args, **kwargs)
           ^^^^^^^^^^^^^^^^^^^^^^^^^^
  File "/opt/airflow/dags/etl_movies_sp.py", line 62, in load_to_staging
    cursor.executemany(sql_insert, df.values.tolist())
  File "/home/airflow/.local/lib/python3.12/site-packages/mysql/connector/cursor_cext.py", line 481, in executemany
    return self.execute(stmt)
           ^^^^^^^^^^^^^^^^^^
  File "/home/airflow/.local/lib/python3.12/site-packages/mysql/connector/cursor_cext.py", line 357, in execute
    result = self._connection.cmd_query(
             ^^^^^^^^^^^^^^^^^^^^^^^^^^^
  File "/home/airflow/.local/lib/python3.12/site-packages/mysql/connector/opentelemetry/context_propagation.py", line 106, in wrapper
    result = method(cnx, *args, **kwargs)
             ^^^^^^^^^^^^^^^^^^^^^^^^^^^^
  File "/home/airflow/.local/lib/python3.12/site-packages/mysql/connector/connection_cext.py", line 714, in cmd_query
    raise get_mysql_exception(
mysql.connector.errors.OperationalError: 1153 (08S01): Got a packet bigger than 'max_allowed_packet' bytes
[2025-01-30T08:21:54.878+0000] {taskinstance.py:1225} INFO - Marking task as UP_FOR_RETRY. dag_id=etl_orders, task_id=load_to_staging, run_id=scheduled__2025-01-29T00:00:00+00:00, execution_date=20250129T000000, start_date=20250130T082104, end_date=20250130T082154
[2025-01-30T08:21:54.920+0000] {taskinstance.py:340} INFO - ::group::Post task execution logs
[2025-01-30T08:21:54.921+0000] {standard_task_runner.py:124} ERROR - Failed to execute job 32 for task load_to_staging (1153 (08S01): Got a packet bigger than 'max_allowed_packet' bytes; 2795)
Traceback (most recent call last):
  File "/home/airflow/.local/lib/python3.12/site-packages/mysql/connector/connection_cext.py", line 706, in cmd_query
    self._cmysql.query(
_mysql_connector.MySQLInterfaceError: Got a packet bigger than 'max_allowed_packet' bytes

The above exception was the direct cause of the following exception:

Traceback (most recent call last):
  File "/home/airflow/.local/lib/python3.12/site-packages/airflow/task/task_runner/standard_task_runner.py", line 117, in _start_by_fork
    ret = args.func(args, dag=self.dag)
          ^^^^^^^^^^^^^^^^^^^^^^^^^^^^^
  File "/home/airflow/.local/lib/python3.12/site-packages/airflow/cli/cli_config.py", line 49, in command
    return func(*args, **kwargs)
           ^^^^^^^^^^^^^^^^^^^^^
  File "/home/airflow/.local/lib/python3.12/site-packages/airflow/utils/cli.py", line 116, in wrapper
    return f(*args, **kwargs)
           ^^^^^^^^^^^^^^^^^^
  File "/home/airflow/.local/lib/python3.12/site-packages/airflow/cli/commands/task_command.py", line 483, in task_run
    task_return_code = _run_task_by_selected_method(args, _dag, ti)
                       ^^^^^^^^^^^^^^^^^^^^^^^^^^^^^^^^^^^^^^^^^^^^
  File "/home/airflow/.local/lib/python3.12/site-packages/airflow/cli/commands/task_command.py", line 256, in _run_task_by_selected_method
    return _run_raw_task(args, ti)
           ^^^^^^^^^^^^^^^^^^^^^^^
  File "/home/airflow/.local/lib/python3.12/site-packages/airflow/cli/commands/task_command.py", line 341, in _run_raw_task
    return ti._run_raw_task(
           ^^^^^^^^^^^^^^^^^
  File "/home/airflow/.local/lib/python3.12/site-packages/airflow/utils/session.py", line 97, in wrapper
    return func(*args, session=session, **kwargs)
           ^^^^^^^^^^^^^^^^^^^^^^^^^^^^^^^^^^^^^^
  File "/home/airflow/.local/lib/python3.12/site-packages/airflow/models/taskinstance.py", line 3005, in _run_raw_task
    return _run_raw_task(
           ^^^^^^^^^^^^^^
  File "/home/airflow/.local/lib/python3.12/site-packages/airflow/models/taskinstance.py", line 273, in _run_raw_task
    TaskInstance._execute_task_with_callbacks(
  File "/home/airflow/.local/lib/python3.12/site-packages/airflow/models/taskinstance.py", line 3159, in _execute_task_with_callbacks
    result = self._execute_task(context, task_orig)
             ^^^^^^^^^^^^^^^^^^^^^^^^^^^^^^^^^^^^^^
  File "/home/airflow/.local/lib/python3.12/site-packages/airflow/models/taskinstance.py", line 3183, in _execute_task
    return _execute_task(self, context, task_orig)
           ^^^^^^^^^^^^^^^^^^^^^^^^^^^^^^^^^^^^^^^
  File "/home/airflow/.local/lib/python3.12/site-packages/airflow/models/taskinstance.py", line 767, in _execute_task
    result = _execute_callable(context=context, **execute_callable_kwargs)
             ^^^^^^^^^^^^^^^^^^^^^^^^^^^^^^^^^^^^^^^^^^^^^^^^^^^^^^^^^^^^^
  File "/home/airflow/.local/lib/python3.12/site-packages/airflow/models/taskinstance.py", line 733, in _execute_callable
    return ExecutionCallableRunner(
           ^^^^^^^^^^^^^^^^^^^^^^^^
  File "/home/airflow/.local/lib/python3.12/site-packages/airflow/utils/operator_helpers.py", line 252, in run
    return self.func(*args, **kwargs)
           ^^^^^^^^^^^^^^^^^^^^^^^^^^
  File "/home/airflow/.local/lib/python3.12/site-packages/airflow/models/baseoperator.py", line 422, in wrapper
    return func(self, *args, **kwargs)
           ^^^^^^^^^^^^^^^^^^^^^^^^^^^
  File "/home/airflow/.local/lib/python3.12/site-packages/airflow/operators/python.py", line 238, in execute
    return_value = self.execute_callable()
                   ^^^^^^^^^^^^^^^^^^^^^^^
  File "/home/airflow/.local/lib/python3.12/site-packages/airflow/operators/python.py", line 256, in execute_callable
    return runner.run(*self.op_args, **self.op_kwargs)
           ^^^^^^^^^^^^^^^^^^^^^^^^^^^^^^^^^^^^^^^^^^^
  File "/home/airflow/.local/lib/python3.12/site-packages/airflow/utils/operator_helpers.py", line 252, in run
    return self.func(*args, **kwargs)
           ^^^^^^^^^^^^^^^^^^^^^^^^^^
  File "/opt/airflow/dags/etl_movies_sp.py", line 62, in load_to_staging
    cursor.executemany(sql_insert, df.values.tolist())
  File "/home/airflow/.local/lib/python3.12/site-packages/mysql/connector/cursor_cext.py", line 481, in executemany
    return self.execute(stmt)
           ^^^^^^^^^^^^^^^^^^
  File "/home/airflow/.local/lib/python3.12/site-packages/mysql/connector/cursor_cext.py", line 357, in execute
    result = self._connection.cmd_query(
             ^^^^^^^^^^^^^^^^^^^^^^^^^^^
  File "/home/airflow/.local/lib/python3.12/site-packages/mysql/connector/opentelemetry/context_propagation.py", line 106, in wrapper
    result = method(cnx, *args, **kwargs)
             ^^^^^^^^^^^^^^^^^^^^^^^^^^^^
  File "/home/airflow/.local/lib/python3.12/site-packages/mysql/connector/connection_cext.py", line 714, in cmd_query
    raise get_mysql_exception(
mysql.connector.errors.OperationalError: 1153 (08S01): Got a packet bigger than 'max_allowed_packet' bytes
[2025-01-30T08:21:55.082+0000] {local_task_job_runner.py:266} INFO - Task exited with return code 1
[2025-01-30T08:21:55.168+0000] {taskinstance.py:3895} INFO - 0 downstream tasks scheduled from follow-on schedule check
[2025-01-30T08:21:55.170+0000] {local_task_job_runner.py:245} INFO - ::endgroup::
