[2025-03-08T02:09:24.854+0000] {local_task_job_runner.py:123} INFO - ::group::Pre task execution logs
[2025-03-08T02:09:24.859+0000] {taskinstance.py:2614} INFO - Dependencies all met for dep_context=non-requeueable deps ti=<TaskInstance: etl_lead_histories.etl_process scheduled__2025-03-07T00:00:00+00:00 [queued]>
[2025-03-08T02:09:24.862+0000] {taskinstance.py:2614} INFO - Dependencies all met for dep_context=requeueable deps ti=<TaskInstance: etl_lead_histories.etl_process scheduled__2025-03-07T00:00:00+00:00 [queued]>
[2025-03-08T02:09:24.862+0000] {taskinstance.py:2867} INFO - Starting attempt 1 of 1
[2025-03-08T02:09:24.869+0000] {taskinstance.py:2890} INFO - Executing <Task(PythonOperator): etl_process> on 2025-03-07 00:00:00+00:00
[2025-03-08T02:09:24.873+0000] {standard_task_runner.py:72} INFO - Started process 90 to run task
[2025-03-08T02:09:24.876+0000] {standard_task_runner.py:104} INFO - Running: ['airflow', 'tasks', 'run', 'etl_lead_histories', 'etl_process', 'scheduled__2025-03-07T00:00:00+00:00', '--job-id', '178', '--raw', '--subdir', 'DAGS_FOLDER/etl-lead-histories.py', '--cfg-path', '/tmp/tmpyx4x1m5x']
[2025-03-08T02:09:24.878+0000] {standard_task_runner.py:105} INFO - Job 178: Subtask etl_process
[2025-03-08T02:09:24.903+0000] {task_command.py:467} INFO - Running <TaskInstance: etl_lead_histories.etl_process scheduled__2025-03-07T00:00:00+00:00 [running]> on host d3ea4d9c26b1
[2025-03-08T02:09:24.934+0000] {taskinstance.py:3134} INFO - Exporting env vars: AIRFLOW_CTX_DAG_OWNER='airflow' AIRFLOW_CTX_DAG_ID='etl_lead_histories' AIRFLOW_CTX_TASK_ID='etl_process' AIRFLOW_CTX_EXECUTION_DATE='2025-03-07T00:00:00+00:00' AIRFLOW_CTX_TRY_NUMBER='1' AIRFLOW_CTX_DAG_RUN_ID='scheduled__2025-03-07T00:00:00+00:00'
[2025-03-08T02:09:24.935+0000] {taskinstance.py:732} INFO - ::endgroup::
[2025-03-08T02:09:24.956+0000] {etl-lead-histories.py:39} INFO - ðŸ”¹ Mengambil data dari PostgreSQL...
[2025-03-08T02:10:05.511+0000] {etl-lead-histories.py:50} INFO - âœ… Data berhasil diambil!
[2025-03-08T02:10:05.513+0000] {etl-lead-histories.py:53} INFO - ðŸ”¹ Memproses data...
[2025-03-08T02:10:05.807+0000] {logging_mixin.py:190} WARNING - /opt/airflow/dags/etl-lead-histories.py:79 UserWarning: Could not infer format, so each element will be parsed individually, falling back to `dateutil`. To ensure parsing is consistent and as-expected, please specify a format.
[2025-03-08T02:10:05.839+0000] {logging_mixin.py:190} WARNING - /opt/airflow/dags/etl-lead-histories.py:80 UserWarning: Could not infer format, so each element will be parsed individually, falling back to `dateutil`. To ensure parsing is consistent and as-expected, please specify a format.
[2025-03-08T02:10:26.509+0000] {etl-lead-histories.py:93} INFO - âœ… Data berhasil dibersihkan!
[2025-03-08T02:10:26.515+0000] {etl-lead-histories.py:96} INFO - ðŸ”¹ Memeriksa data yang sudah ada di MySQL...
[2025-03-08T02:10:26.699+0000] {taskinstance.py:3313} ERROR - Task failed with exception
Traceback (most recent call last):
  File "/home/airflow/.local/lib/python3.12/site-packages/airflow/models/taskinstance.py", line 768, in _execute_task
    result = _execute_callable(context=context, **execute_callable_kwargs)
             ^^^^^^^^^^^^^^^^^^^^^^^^^^^^^^^^^^^^^^^^^^^^^^^^^^^^^^^^^^^^^
  File "/home/airflow/.local/lib/python3.12/site-packages/airflow/models/taskinstance.py", line 734, in _execute_callable
    return ExecutionCallableRunner(
           ^^^^^^^^^^^^^^^^^^^^^^^^
  File "/home/airflow/.local/lib/python3.12/site-packages/airflow/utils/operator_helpers.py", line 252, in run
    return self.func(*args, **kwargs)
           ^^^^^^^^^^^^^^^^^^^^^^^^^^
  File "/home/airflow/.local/lib/python3.12/site-packages/airflow/models/baseoperator.py", line 424, in wrapper
    return func(self, *args, **kwargs)
           ^^^^^^^^^^^^^^^^^^^^^^^^^^^
  File "/home/airflow/.local/lib/python3.12/site-packages/airflow/operators/python.py", line 238, in execute
    return_value = self.execute_callable()
                   ^^^^^^^^^^^^^^^^^^^^^^^
  File "/home/airflow/.local/lib/python3.12/site-packages/airflow/operators/python.py", line 256, in execute_callable
    return runner.run(*self.op_args, **self.op_kwargs)
           ^^^^^^^^^^^^^^^^^^^^^^^^^^^^^^^^^^^^^^^^^^^
  File "/home/airflow/.local/lib/python3.12/site-packages/airflow/utils/operator_helpers.py", line 252, in run
    return self.func(*args, **kwargs)
           ^^^^^^^^^^^^^^^^^^^^^^^^^^
  File "/opt/airflow/dags/etl-lead-histories.py", line 97, in etl_process
    conn_target = get_mysql_connection()
                  ^^^^^^^^^^^^^^^^^^^^^^
  File "/opt/airflow/dags/etl-lead-histories.py", line 35, in get_mysql_connection
    return pymysql.connect(**DB_TARGET)
           ^^^^^^^^^^^^^^^^^^^^^^^^^^^^
  File "/home/airflow/.local/lib/python3.12/site-packages/pymysql/connections.py", line 361, in __init__
    self.connect()
  File "/home/airflow/.local/lib/python3.12/site-packages/pymysql/connections.py", line 669, in connect
    self._request_authentication()
  File "/home/airflow/.local/lib/python3.12/site-packages/pymysql/connections.py", line 979, in _request_authentication
    auth_packet = _auth.caching_sha2_password_auth(self, auth_packet)
                  ^^^^^^^^^^^^^^^^^^^^^^^^^^^^^^^^^^^^^^^^^^^^^^^^^^^
  File "/home/airflow/.local/lib/python3.12/site-packages/pymysql/_auth.py", line 241, in caching_sha2_password_auth
    pkt = conn._read_packet()
          ^^^^^^^^^^^^^^^^^^^
  File "/home/airflow/.local/lib/python3.12/site-packages/pymysql/connections.py", line 775, in _read_packet
    packet.raise_for_error()
  File "/home/airflow/.local/lib/python3.12/site-packages/pymysql/protocol.py", line 219, in raise_for_error
    err.raise_mysql_exception(self._data)
  File "/home/airflow/.local/lib/python3.12/site-packages/pymysql/err.py", line 150, in raise_mysql_exception
    raise errorclass(errno, errval)
pymysql.err.OperationalError: (1044, "Access denied for user 'mysql'@'%' to database 'dashboard'")
[2025-03-08T02:10:26.735+0000] {taskinstance.py:1226} INFO - Marking task as FAILED. dag_id=etl_lead_histories, task_id=etl_process, run_id=scheduled__2025-03-07T00:00:00+00:00, execution_date=20250307T000000, start_date=20250308T020924, end_date=20250308T021026
[2025-03-08T02:10:26.768+0000] {taskinstance.py:341} INFO - ::group::Post task execution logs
[2025-03-08T02:10:26.769+0000] {standard_task_runner.py:124} ERROR - Failed to execute job 178 for task etl_process ((1044, "Access denied for user 'mysql'@'%' to database 'dashboard'"); 90)
Traceback (most recent call last):
  File "/home/airflow/.local/lib/python3.12/site-packages/airflow/task/task_runner/standard_task_runner.py", line 117, in _start_by_fork
    ret = args.func(args, dag=self.dag)
          ^^^^^^^^^^^^^^^^^^^^^^^^^^^^^
  File "/home/airflow/.local/lib/python3.12/site-packages/airflow/cli/cli_config.py", line 49, in command
    return func(*args, **kwargs)
           ^^^^^^^^^^^^^^^^^^^^^
  File "/home/airflow/.local/lib/python3.12/site-packages/airflow/utils/cli.py", line 116, in wrapper
    return f(*args, **kwargs)
           ^^^^^^^^^^^^^^^^^^
  File "/home/airflow/.local/lib/python3.12/site-packages/airflow/cli/commands/task_command.py", line 483, in task_run
    task_return_code = _run_task_by_selected_method(args, _dag, ti)
                       ^^^^^^^^^^^^^^^^^^^^^^^^^^^^^^^^^^^^^^^^^^^^
  File "/home/airflow/.local/lib/python3.12/site-packages/airflow/cli/commands/task_command.py", line 256, in _run_task_by_selected_method
    return _run_raw_task(args, ti)
           ^^^^^^^^^^^^^^^^^^^^^^^
  File "/home/airflow/.local/lib/python3.12/site-packages/airflow/cli/commands/task_command.py", line 341, in _run_raw_task
    return ti._run_raw_task(
           ^^^^^^^^^^^^^^^^^
  File "/home/airflow/.local/lib/python3.12/site-packages/airflow/utils/session.py", line 97, in wrapper
    return func(*args, session=session, **kwargs)
           ^^^^^^^^^^^^^^^^^^^^^^^^^^^^^^^^^^^^^^
  File "/home/airflow/.local/lib/python3.12/site-packages/airflow/models/taskinstance.py", line 3006, in _run_raw_task
    return _run_raw_task(
           ^^^^^^^^^^^^^^
  File "/home/airflow/.local/lib/python3.12/site-packages/airflow/models/taskinstance.py", line 274, in _run_raw_task
    TaskInstance._execute_task_with_callbacks(
  File "/home/airflow/.local/lib/python3.12/site-packages/airflow/models/taskinstance.py", line 3161, in _execute_task_with_callbacks
    result = self._execute_task(context, task_orig)
             ^^^^^^^^^^^^^^^^^^^^^^^^^^^^^^^^^^^^^^
  File "/home/airflow/.local/lib/python3.12/site-packages/airflow/models/taskinstance.py", line 3185, in _execute_task
    return _execute_task(self, context, task_orig)
           ^^^^^^^^^^^^^^^^^^^^^^^^^^^^^^^^^^^^^^^
  File "/home/airflow/.local/lib/python3.12/site-packages/airflow/models/taskinstance.py", line 768, in _execute_task
    result = _execute_callable(context=context, **execute_callable_kwargs)
             ^^^^^^^^^^^^^^^^^^^^^^^^^^^^^^^^^^^^^^^^^^^^^^^^^^^^^^^^^^^^^
  File "/home/airflow/.local/lib/python3.12/site-packages/airflow/models/taskinstance.py", line 734, in _execute_callable
    return ExecutionCallableRunner(
           ^^^^^^^^^^^^^^^^^^^^^^^^
  File "/home/airflow/.local/lib/python3.12/site-packages/airflow/utils/operator_helpers.py", line 252, in run
    return self.func(*args, **kwargs)
           ^^^^^^^^^^^^^^^^^^^^^^^^^^
  File "/home/airflow/.local/lib/python3.12/site-packages/airflow/models/baseoperator.py", line 424, in wrapper
    return func(self, *args, **kwargs)
           ^^^^^^^^^^^^^^^^^^^^^^^^^^^
  File "/home/airflow/.local/lib/python3.12/site-packages/airflow/operators/python.py", line 238, in execute
    return_value = self.execute_callable()
                   ^^^^^^^^^^^^^^^^^^^^^^^
  File "/home/airflow/.local/lib/python3.12/site-packages/airflow/operators/python.py", line 256, in execute_callable
    return runner.run(*self.op_args, **self.op_kwargs)
           ^^^^^^^^^^^^^^^^^^^^^^^^^^^^^^^^^^^^^^^^^^^
  File "/home/airflow/.local/lib/python3.12/site-packages/airflow/utils/operator_helpers.py", line 252, in run
    return self.func(*args, **kwargs)
           ^^^^^^^^^^^^^^^^^^^^^^^^^^
  File "/opt/airflow/dags/etl-lead-histories.py", line 97, in etl_process
    conn_target = get_mysql_connection()
                  ^^^^^^^^^^^^^^^^^^^^^^
  File "/opt/airflow/dags/etl-lead-histories.py", line 35, in get_mysql_connection
    return pymysql.connect(**DB_TARGET)
           ^^^^^^^^^^^^^^^^^^^^^^^^^^^^
  File "/home/airflow/.local/lib/python3.12/site-packages/pymysql/connections.py", line 361, in __init__
    self.connect()
  File "/home/airflow/.local/lib/python3.12/site-packages/pymysql/connections.py", line 669, in connect
    self._request_authentication()
  File "/home/airflow/.local/lib/python3.12/site-packages/pymysql/connections.py", line 979, in _request_authentication
    auth_packet = _auth.caching_sha2_password_auth(self, auth_packet)
                  ^^^^^^^^^^^^^^^^^^^^^^^^^^^^^^^^^^^^^^^^^^^^^^^^^^^
  File "/home/airflow/.local/lib/python3.12/site-packages/pymysql/_auth.py", line 241, in caching_sha2_password_auth
    pkt = conn._read_packet()
          ^^^^^^^^^^^^^^^^^^^
  File "/home/airflow/.local/lib/python3.12/site-packages/pymysql/connections.py", line 775, in _read_packet
    packet.raise_for_error()
  File "/home/airflow/.local/lib/python3.12/site-packages/pymysql/protocol.py", line 219, in raise_for_error
    err.raise_mysql_exception(self._data)
  File "/home/airflow/.local/lib/python3.12/site-packages/pymysql/err.py", line 150, in raise_mysql_exception
    raise errorclass(errno, errval)
pymysql.err.OperationalError: (1044, "Access denied for user 'mysql'@'%' to database 'dashboard'")
[2025-03-08T02:10:26.822+0000] {local_task_job_runner.py:266} INFO - Task exited with return code 1
[2025-03-08T02:10:26.858+0000] {taskinstance.py:3901} INFO - 0 downstream tasks scheduled from follow-on schedule check
[2025-03-08T02:10:26.861+0000] {local_task_job_runner.py:245} INFO - ::endgroup::
